Workbook

Sheet README
B2: KIX — VENUE FINANCIAL MODEL
B3: Bottom-up capacity model - 18,000 SF vs 35,000 SF - benchmarked to a real ESA-equipped venue
B5: What this model does
B6: Builds venue revenue from the bottom up - stations x throughput x operating hours x utilisation - instead of assuming a revenue target. Every line traces back to a driver you can change.
B7: It runs two footprints side by side: an 18,000 SF box and the 35,000 SF box in the current KIX plan, so the trade-off between size, capital and payback is explicit.
B8: It is calibrated against Ballpark Brighton - the only published financial case study of an ESA-equipped entertainment venue - so the assumptions are anchored to a real operating comparable.
B10: How to use it
B11: 1. Open 'Assumptions'. Every blue cell is an input. Change them; everything else recalculates.
B12: 2. 'Revenue Build' shows the stabilised (Year 3) revenue for each footprint and cross-checks it against the benchmark's revenue density.
B13: 3. 'Capex' builds total project cost excluding real estate.
B14: 4. 'P&L' applies the ramp to produce five years for each footprint.
B15: 5. 'Returns & Scenarios' gives payback, cash-on-cash, downside/base/upside, and a direct reconciliation against the numbers in the current KIX business plan.
... B31: All other assumptions are management estimates entered as inputs and flagged blue in 'Assumptions'.

Sheet Benchmark
A1: BENCHMARK — BALLPARK BRIGHTON
A2: The only published financial case study of an ESA-equipped entertainment venue. Source: Elite Skills Arena, 18 May 2026.
A4: FX AND REPORTED FIGURES
B5: GBP | C5: USD | D5: Note
A6: GBP / USD rate | B6: 1.3 | D6: Edit to change every USD figure below
A7: Footprint (sq ft) | B7: 5382 | D7: 500 sq m as reported, converted at 10.764 sq ft per sq m
A8: Annual revenue | B8: 192000 | C8: =B8*$B$6 | D8: GBP 16,000 per month as reported
A9: ESA equipment cost | B9: 69000 | C9: =B9*$B$6 | D9: Fast Feet, ICON 6m, Precision Wall
A10: Total opening cost | B10: 200000 | C10: =B10*$B$6 | D10: Converted restaurant, not a raw warehouse shell
A11: Annual rent | B11: 45000 | C11: =B11*$B$6 | D11: GBP 3,750 per month as reported
A12: Bar / F&B share of revenue | B12: 0.15 | D12: Low. A proper F&B operation runs 25-40% in this category
A14: DERIVED DENSITY
A15: Revenue per SF per year | B15: =B8/B7 | C15: =C8/B7 | D15: THE anchor number for this whole model
A16: Equipment cost per SF | B16: =B9/B7 | C16: =C9/B7
A17: Total capex per SF | B17: =B10/B7 | C17: =C10/B7 | D17: Fitted restaurant conversion. A US warehouse shell costs materially more
A18: Equipment as % of total capex | B18: =B9/B10 | D18: 34.5% as reported — useful sense-check on the KIX capex mix
A19: Rent per SF per year | B19: =B11/B7 | C19: =C11/B7
A21: THE KIX PLAN, AS WRITTEN
A22: Planned footprint (SF) | B22: 35000 | D22: Midpoint of the 30-40k SF target, plan section 9
A23: Planned stabilised revenue (Year 3) | B23: 5000000 | D23: Plan section 26
A24: Planned Year 3 EBITDA | B24: 1300000 | D24: Plan section 26 — 26% margin
A25: Planned buildout (excl. real estate) | B25: 1500000 | D25: Midpoint of the $1.0-2.0M target, plan section 9
A26: Implied revenue per SF | B26: =B23/B22
A27: Multiple of Ballpark density | B27: =B26/C15 | D27: The plan assumes this many times the revenue density of the benchmark
A28: Implied simple payback (years) | B28: =B25/B24 | D28: A payback this fast is the number investors will challenge first
A30: Reading this sheet
A31: Ballpark is a husband-and-wife independent in a converted restaurant with no membership programme and F&B at only 15%.
A32: A professionally capitalised venue should beat it. But the KIX plan assumes it beats it by roughly 3x per square foot,
A33: in a footprint over six times larger — and larger boxes almost always earn LESS per SF, not more, because circulation,
A34: back-of-house, party rooms and seating do not sell tickets. That gap is the single biggest risk in the plan.

Sheet Assumptions
A1: ASSUMPTIONS
A2: Every blue cell is an input. Yellow fill marks the assumptions that move the answer most.
B4: Scenario A | C4: Scenario B | D4: Note
B5: 18,000 SF | C5: 35,000 SF
A6: FOOTPRINT & LAYOUT
A7: Total footprint (SF) | B7: 18000 | C7: 35000 | D7: The core trade-off this model tests
A8: Attraction stations | B8: 14 | C8: 22 | D8: ESA units: Power Shot, Precision Wall, Fast Feet, Dribble Lane, Panenka, Sprint Lane
A9: Party rooms | B9: 2 | C9: 4
A10: Small-sided pitches | B10: 1 | C10: 3 | D10: Drives league capacity
A12: CAPACITY & THROUGHPUT
A13: Play cycles per station per hour | B13: 7 | C13: 7 | D13: Allows for changeover and group rotation
A14: Operating hours per week | B14: 85 | C14: 85 | D14: ~12h weekdays, ~13h weekends
A15: Weeks open per year | B15: 51 | C15: 51
A16: Blended station utilisation | B16: 0.2 | C16: 0.2 | D16: THE most sensitive assumption. Demand concentrates into after-school and weekends
A17: Play cycles per walk-in visit | B17: 5 | C17: 5 | D17: A visitor buys a game pack, not one play
A19: PRICING & SPEND
A20: Attraction spend per walk-in visit ($) | B20: 26 | C20: 26 | D20: Game pack price point
A21: F&B spend per head of footfall ($) | B21: 6 | C21: 6 | D21: Blended across all footfall. Ballpark achieves far less; a real F&B programme should beat this
A22: Retail spend per head of footfall ($) | B22: 0.9 | C22: 0.9
A24: MEMBERSHIP
A25: Average active members | B25: 300 | C25: 500 | D25: Net of churn, averaged across the year
A26: Average monthly fee ($) | B26: 85 | C26: 85 | D26: Blended across PLAY/PLAYER/PRO/FAMILY tiers
A27: Member visits per member per month | B27: 2.5 | C27: 2.5 | D27: Feeds footfall for F&B and retail. Member play is covered by the fee, not charged again
A29: PROGRAMMES
A30: Parties per year | B30: 300 | C30: 450 | D30: Ballpark runs 1-2 per week in 5,400 SF
A31: Average party package ($) | B31: 600 | C31: 600
A32: Average guests per party | B32: 16 | C32: 16
A33: Academy & clinics revenue ($) | B33: 220000 | C33: 340000
A34: Academy participant visits (annual) | B34: 9000 | C34: 14000
A35: Camps revenue ($) | B35: 120000 | C35: 190000 | D35: School holidays and summer
A36: Camp participant-days (annual) | B36: 3000 | C36: 4700
A37: Leagues revenue ($) | B37: 150000 | C37: 320000 | D37: Scales with number of pitches
A38: League player-visits (annual) | B38: 7000 | C38: 15000
A39: Corporate & private events revenue ($) | B39: 140000 | C39: 240000
A40: Corporate event attendees (annual) | B40: 2800 | C40: 4800
A41: Sponsorship revenue ($) | B41: 40000 | C41: 60000
A43: CAPEX
A44: Fit-out cost per SF ($) | B44: 60 | C44: 60 | D44: Warehouse shell to finished venue. Lean 55 / realistic 85 / premium 120
A45: Cost per attraction station installed ($) | B45: 24000 | C45: 24000 | D45: ESA list plus freight, duty, install. Benchmark implies ~$18k before US landed costs
A46: FF&E, bar & kitchen build ($) | B46: 220000 | C46: 380000
...

Sheet Revenue Build
A1: REVENUE BUILD — STABILISED (YEAR 3)
A2: Built from capacity, not from a target.
B4: 18,000 SF | C4: 35,000 SF | D4: Note
A5: CAPACITY
A6: Play cycles available per hour | B6: =Assumptions!$B$8*Assumptions!$B$13 | C6: =Assumptions!$C$8*Assumptions!$C$13
A7: Play cycles available per year | B7: =B6*Assumptions!$B$14*Assumptions!$B$15 | C7: =C6*Assumptions!$C$14*Assumptions!$C$15 | D7: Theoretical maximum at 100% utilisation
A8: Play cycles sold | B8: =B7*Assumptions!$B$16 | C8: =C7*Assumptions!$C$16
A9: Walk-in visits per year | B9: =B8/Assumptions!$B$17 | C9: =C8/Assumptions!$C$17
A11: FOOTFALL (drives F&B and retail)
A12: Walk-in visitors | B12: =B9 | C12: =C9
A13: Member visits | B13: =Assumptions!$B$25*Assumptions!$B$27*12 | C13: =Assumptions!$C$25*Assumptions!$C$27*12
A14: Party guests | B14: =Assumptions!$B$30*Assumptions!$B$32 | C14: =Assumptions!$C$30*Assumptions!$C$32
A15: Academy participants | B15: =Assumptions!$B$34 | C15: =Assumptions!$C$34
A16: Camp participant-days | B16: =Assumptions!$B$36 | C16: =Assumptions!$C$36
A17: League player-visits | B17: =Assumptions!$B$38 | C17: =Assumptions!$C$38
A18: Corporate attendees | B18: =Assumptions!$B$40 | C18: =Assumptions!$C$40
A19: Total annual footfall | B19: =SUM(B12:B18) | C19: =SUM(C12:C18)
A21: REVENUE STREAMS
A22: 1. Walk-in pay-to-play | B22: =B12*Assumptions!$B$20 | C22: =C12*Assumptions!$C$20
A23: 2. Membership | B23: =Assumptions!$B$25*Assumptions!$B$26*12 | C23: =Assumptions!$C$25*Assumptions!$C$26*12 | D23: Member play is covered by the fee
A24: 3. Parties | B24: =Assumptions!$B$30*Assumptions!$B$31 | C24: =Assumptions!$C$30*Assumptions!$C$31
A25: 4. Academy & clinics | B25: =Assumptions!$B$33 | C25: =Assumptions!$C$33
A26: 5. Camps | B26: =Assumptions!$B$35 | C26: =Assumptions!$C$35
A27: 6. Leagues | B27: =Assumptions!$B$37 | C27: =Assumptions!$C$37
A28: 7. Corporate & private events | B28: =Assumptions!$B$39 | C28: =Assumptions!$C$39
A29: 8. Food & beverage | B29: =B19*Assumptions!$B$21 | C29: =C19*Assumptions!$C$21 | D29: The margin engine. Do not under-build this
A30: 9. Retail | B30: =B19*Assumptions!$B$22 | C30: =C19*Assumptions!$C$22
A31: 10. Sponsorship | B31: =Assumptions!$B$41 | C31: =Assumptions!$C$41
A32: STABILISED REVENUE | B32: =SUM(B22:B31) | C32: =SUM(C22:C31)
A34: MIX CHECK
A35: F&B as % of revenue | B35: =B29/B32 | C35: =C29/C32 | D35: Benchmark achieves 15%. Category norm is 25-40%
A36: Membership as % of revenue | B36: =B23/B32 | C36: =C23/C32 | D36: Reality check on the 'recurring revenue platform' story
A37: Recurring + programmed as % of revenue | B37: =(B23+B25+B26+B27)/B32 | C37: =(C23+C25+C26+C27)/C32
A39: DENSITY CROSS-CHECK
A40: Revenue per SF per year | B40: =B32/Assumptions!$B$7 | C40: =C32/Assumptions!$C$7
A41: Ballpark Brighton benchmark ($/SF) | B41: =Benchmark!$C$15 | C41: =Benchmark!$C$15
A42: Multiple of benchmark density | B42: =B40/B41 | C42: =C40/C41 | D42: How much better than the comparable this model assumes you operate
A43: vs KIX plan revenue ($5.0M) | B43: =B32/Benchmark!$B$23 | C43: =C32/Benchmark!$B$23 | D43: This model as a percentage of the plan's Year 3 number
A45: Note: member attraction play is not charged twice — the membership fee covers it, and member visits appear in footfall only, where they drive F&B and retail.

Sheet Capex
A1: CAPEX — TOTAL PROJECT COST
A2: Excludes real estate acquisition.
B4: 18,000 SF | C4: 35,000 SF | D4: Note
A5: PROJECT COST
A6: Fit-out (shell to finished venue) | B6: =Assumptions!$B$7*Assumptions!$B$44 | C6: =Assumptions!$C$7*Assumptions!$C$44 | D6: HVAC, power, restrooms, fire, ADA, flooring, lighting, finishes
A7: Attraction equipment (ESA) | B7: =Assumptions!$B$8*Assumptions!$B$45 | C7: =Assumptions!$C$8*Assumptions!$C$45 | D7: Landed and installed
A8: FF&E, bar & kitchen | B8: =Assumptions!$B$46 | C8: =Assumptions!$C$46
A9: Technology | B9: =Assumptions!$B$47 | C9: =Assumptions!$C$47
A10: Pre-opening | B10: =Assumptions!$B$48 | C10: =Assumptions!$C$48
A11: Subtotal | B11: =SUM(B6:B10) | C11: =SUM(C6:C10)
A12: Contingency | B12: =B11*Assumptions!$B$49 | C12: =C11*Assumptions!$C$49
A13: TOTAL PROJECT COST | B13: =B11+B12 | C13: =C11+C12
A15: CAPEX CHECKS
A16: Cost per SF | B16: =B13/Assumptions!$B$7 | C16: =C13/Assumptions!$C$7
A17: Ballpark benchmark cost per SF | B17: =Benchmark!$C$17 | C17: =Benchmark!$C$17 | D17: Benchmark was a fitted restaurant, so a warehouse shell should cost more
A18: Equipment as % of total capex | B18: =B7/B13 | C18: =C7/C13 | D18: Benchmark ratio is 34.5%
A19: vs KIX planned buildout ($1.5M) | B19: =B13/Benchmark!$B$25 | C19: =C13/Benchmark!$B$25 | D19: How far the plan's buildout budget is from a realistic build

Sheet P&L
A1: FIVE YEAR P&L
A2: Stabilised revenue from 'Revenue Build', scaled by the ramp in 'Assumptions'.
A5: SCENARIO A — 18,000 SF
B6: Year 1 | C6: Year 2 | D6: Year 3 | E6: Year 4 | F6: Year 5 | G6: Note
A7: Revenue | B7: ='Revenue Build'!$B$32*Assumptions!$B$64 | C7: ='Revenue Build'!$B$32*Assumptions!$B$65 | D7: ='Revenue Build'!$B$32*Assumptions!$B$66 | E7: ='Revenue Build'!$B$32*Assumptions!$B$67 | F7: ='Revenue Build'!$B$32*Assumptions!$B$68 | G7: Ramp applied to stabilised revenue
A8: of which F&B | B8: =B7*'Revenue Build'!$B$35 | C8: =C7*'Revenue Build'!$B$35 | D8: =D7*'Revenue Build'!$B$35 | E8: =E7*'Revenue Build'!$B$35 | F8: =F7*'Revenue Build'!$B$35
A10: Operating costs
A11: Labour | B11: =B7*Assumptions!$B$52 | C11: =C7*Assumptions!$B$52 | D11: =D7*Assumptions!$B$52 | E11: =E7*Assumptions!$B$52 | F11: =F7*Assumptions!$B$52
A12: F&B COGS | B12: =B8*Assumptions!$B$57 | C12: =C8*Assumptions!$B$57 | D12: =D8*Assumptions!$B$57 | E12: =E8*Assumptions!$B$57 | F12: =F8*Assumptions!$B$57
A13: Rent | B13: =Assumptions!$B$7*Assumptions!$B$53 | C13: =Assumptions!$B$7*Assumptions!$B$53 | D13: =Assumptions!$B$7*Assumptions!$B$53 | E13: =Assumptions!$B$7*Assumptions!$B$53 | F13: =Assumptions!$B$7*Assumptions!$B$53 | G13: Fixed — does not scale with the ramp
A14: Utilities | B14: =Assumptions!$B$7*Assumptions!$B$54 | C14: =Assumptions!$B$7*Assumptions!$B$54 | D14: =Assumptions!$B$7*Assumptions!$B$54 | E14: =Assumptions!$B$7*Assumptions!$B$54 | F14: =Assumptions!$B$7*Assumptions!$B$54
A15: Insurance | B15: =Assumptions!$B$7*Assumptions!$B$55 | C15: =Assumptions!$B$7*Assumptions!$B$55 | D15: =Assumptions!$B$7*Assumptions!$B$55 | E15: =Assumptions!$B$7*Assumptions!$B$55 | F15: =Assumptions!$B$7*Assumptions!$B$55
A16: Marketing | B16: =B7*Assumptions!$B$56 | C16: =C7*Assumptions!$B$56 | D16: =D7*Assumptions!$B$56 | E16: =E7*Assumptions!$B$56 | F16: =F7*Assumptions!$B$56
A17: Equipment service | B17: =Capex!$B$7*Assumptions!$B$58 | C17: =Capex!$B$7*Assumptions!$B$58 | D17: =Capex!$B$7*Assumptions!$B$58 | E17: =Capex!$B$7*Assumptions!$B$58 | F17: =Capex!$B$7*Assumptions!$B$58
A18: Software & systems | B18: =Assumptions!$B$59 | C18: =Assumptions!$B$59 | D18: =Assumptions!$B$59 | E18: =Assumptions!$B$59 | F18: =Assumptions!$B$59
A19: Repairs & renewals | B19: =B7*Assumptions!$B$60 | C19: =C7*Assumptions!$B$60 | D19: =D7*Assumptions!$B$60 | E19: =E7*Assumptions!$B$60 | F19: =F7*Assumptions!$B$60
A20: Admin & other | B20: =B7*Assumptions!$B$61 | C20: =C7*Assumptions!$B$61 | D20: =D7*Assumptions!$B$61 | E20: =E7*Assumptions!$B$61 | F20: =F7*Assumptions!$B$61
A21: Total operating costs | B21: =SUM(B11:B20) | C21: =SUM(C11:C20) | D21: =SUM(D11:D20) | E21: =SUM(E11:E20) | F21: =SUM(F11:F20)
A23: EBITDA | B23: =B7-B21 | C23: =C7-C21 | D23: =D7-D21 | E23: =E7-E21 | F23: =F7-F21 | G23: Venue-level EBITDA, before corporate overhead
A24: EBITDA margin | B24: =IF(B7=0,0,B23/B7) | C24: =IF(C7=0,0,C23/C7) | D24: =IF(D7=0,0,D23/D7) | E24: =IF(E7=0,0,E23/E7) | F24: =IF(F7=0,0,F23/F7)
A25: Cumulative EBITDA | B25: =B23 | C25: =B25+C23 | D25: =C25+D23 | E25: =D25+E23 | F25: =E25+F23
A28: SCENARIO B — 35,000 SF
B29: Year 1 | C29: Year 2 | D29: Year 3 | E29: Year 4 | F29: Year 5 | G29: Note
A30: Revenue | B30: ='Revenue Build'!$C$32*Assumptions!$C$64 | C30: ='Revenue Build'!$C$32*Assumptions!$C$65 | D30: ='Revenue Build'!$C$32*Assumptions!$C$66 | E30: ='Revenue Build'!$C$32*Assumptions!$C$67 | F30: ='Revenue Build'!$C$32*Assumptions!$C$68
A31: of which F&B | B31: =B30*'Revenue Build'!$C$35 | C31: =C30*'Revenue Build'!$C$35 | D31: =D30*'Revenue Build'!$C$35 | E31: =E30*'Revenue Build'!$C$35 | F31: =F30*'Revenue Build'!$C$35
A33: Operating costs
A34: Labour | B34: =B30*Assumptions!$C$52 | C34: =C30*Assumptions!$C$52 | D34: =D30*Assumptions!$C$52 | E34: =E30*Assumptions!$C$52 | F34: =F30*Assumptions!$C$52
A35: F&B COGS | B35: =B31*Assumptions!$C$57 | C35: =C31*Assumptions!$C$57 | D35: =D31*Assumptions!$C$57 | E35: =E31*Assumptions!$C$57 | F35: =F31*Assumptions!$C$57
A36: Rent | B36: =Assumptions!$C$7*Assumptions!$C$53 | C36: =Assumptions!$C$7*Assumptions!$C$53 | D36: =Assumptions!$C$7*Assumptions!$C$53 | E36: =Assumptions!$C$7*Assumptions!$C$53 | F36: =Assumptions!$C$7*Assumptions!$C$53
A37: Utilities | B37: =Assumptions!$C$7*Assumptions!$C$54 | C37: =Assumptions!$C$7*Assumptions!$C$54 | D37: =Assumptions!$C$7*Assumptions!$C$54 | E37: =Assumptions!$C$7*Assumptions!$C$54 | F37: =Assumptions!$C$7*Assumptions!$C$54
A38: Insurance | B38: =Assumptions!$C$7*Assumptions!$C$55 | C38: =Assumptions!$C$7*Assumptions!$C$55 | D38: =Assumptions!$C$7*Assumptions!$C$55 | E38: =Assumptions!$C$7*Assumptions!$C$55 | F38: =Assumptions!$C$7*Assumptions!$C$55
A39: Marketing | B39: =B30*Assumptions!$C$56 | C39: =C30*Assumptions!$C$56 | D39: =D30*Assumptions!$C$56 | E39: =E30*Assumptions!$C$56 | F39: =F30*Assumptions!$C$56
A40: Equipment service | B40: =Capex!$C$7*Assumptions!$C$58 | C40: =Capex!$C$7*Assumptions!$C$58 | D40: =Capex!$C$7*Assumptions!$C$58 | E40: =Capex!$C$7*Assumptions!$C$58 | F40: =Capex!$C$7*Assumptions!$C$58
A41: Software & systems | B41: =Assumptions!$C$59 | C41: =Assumptions!$C$59 | D41: =Assumptions!$C$59 | E41: =Assumptions!$C$59 | F41: =Assumptions!$C$59
A42: Repairs & renewals | B42: =B30*Assumptions!$C$60 | C42: =C30*Assumptions!$C$60 | D42: =D30*Assumptions!$C$60 | E42: =E30*Assumptions!$C$60 | F42: =F30*Assumptions!$C$60
A43: Admin & other | B43: =B30*Assumptions!$C$61 | C43: =C30*Assumptions!$C$61 | D43: =D30*Assumptions!$C$61 | E43: =E30*Assumptions!$C$61 | F43: =F30*Assumptions!$C$61
A44: Total operating costs | B44: =SUM(B34:B43) | C44: =SUM(C34:C43) | D44: =SUM(D34:D43) | E44: =SUM(E34:E43) | F44: =SUM(F34:F43)
A46: EBITDA | B46: =B30-B44 | C46: =C30-C44 | D46: =D30-D44 | E46: =E30-E44 | F46: =F30-F44 | G46: Venue-level EBITDA, before corporate overhead
A47: EBITDA margin | B47: =IF(B30=0,0,B46/B30) | C47: =IF(C30=0,0,C46/C30) | D47: =IF(D30=0,0,D46/D30) | E47: =IF(E30=0,0,E46/E30) | F47: =IF(F30=0,0,F46/F30)
A48: Cumulative EBITDA | B48: =B46 | C48: =B48+C46 | D48: =C48+D46 | E48: =D48+E46 | F48: =E48+F46

Sheet Returns & Scenarios
A1: RETURNS & SCENARIOS
A2: Venue-level returns on total project cost, excluding real estate.
B4: 18,000 SF | C4: 35,000 SF | D4: Note
A5: BASE CASE RETURNS
A6: Total project cost | B6: =Capex!$B$13 | C6: =Capex!$C$13
A7: Year 3 revenue (stabilised) | B7: =P&L!D7 | C7: =P&L!D30
A8: Year 3 EBITDA | B8: =P&L!D23 | C8: =P&L!D46
A9: Year 3 EBITDA margin | B9: =P&L!D24 | C9: =P&L!D47
A10: Year 5 EBITDA | B10: =P&L!F23 | C10: =P&L!F46
A11: Cumulative 5-year EBITDA | B11: =P&L!F25 | C11: =P&L!F48
A12: Simple payback on stabilised EBITDA (years) | B12: =IF(B8<=0,"n/a",B6/B8) | C12: =IF(C8<=0,"n/a",C6/C8) | D12: Capex divided by Year 3 EBITDA
A13: Year 3 cash-on-cash return | B13: =B8/B6 | C13: =C8/C6
A14: 5-year EBITDA as % of capex | B14: =B11/B6 | C14: =C11/C6 | D14: Above 100% means the venue has repaid its build within five years
A15: Capex per $1 of stabilised revenue | B15: =B6/B7 | C15: =C6/C7 | D15: Lower is better. This is where the smaller box tends to win
A17: SENSITIVITY — REVENUE SCENARIOS
B18: Revenue | C18: multiplier
A19: Downside | B19: 0.7 | D19: Utilisation and spend disappoint; closer to benchmark density
A20: Base | B20: 1 | D20: The model as built
A21: Upside | B21: 1.25 | D21: Strong utilisation, F&B and membership outperform
A23: 18,000 SF | B23: Revenue | C23: EBITDA | D23: Payback (yrs)
A24: Downside | B24: ='Returns & Scenarios'!$B$7*$B$19 | C24: =B24-(B24*(Assumptions!$B$52+Assumptions!$B$56+Assumptions!$B$60+Assumptions!$B$61)+B24*'Revenue Build'!$B$35*Assumptions!$B$57+Assumptions!$B$7*(Assumptions!$B$53+Assumptions!$B$54+Assumptions!$B$55)+Capex!$B$7*Assumptions!$B$58+Assumptions!$B$59) | D24: =IF(C24<=0,"n/a",$B$6/C24)
A25: Base | B25: ='Returns & Scenarios'!$B$7*$B$20 | C25: =B25-(B25*(Assumptions!$B$52+Assumptions!$B$56+Assumptions!$B$60+Assumptions!$B$61)+B25*'Revenue Build'!$B$35*Assumptions!$B$57+Assumptions!$B$7*(Assumptions!$B$53+Assumptions!$B$54+Assumptions!$B$55)+Capex!$B$7*Assumptions!$B$58+Assumptions!$B$59) | D25: =IF(C25<=0,"n/a",$B$6/C25)
A26: Upside | B26: ='Returns & Scenarios'!$B$7*$B$21 | C26: =B26-(B26*(Assumptions!$B$52+Assumptions!$B$56+Assumptions!$B$60+Assumptions!$B$61)+B26*'Revenue Build'!$B$35*Assumptions!$B$57+Assumptions!$B$7*(Assumptions!$B$53+Assumptions!$B$54+Assumptions!$B$55)+Capex!$B$7*Assumptions!$B$58+Assumptions!$B$59) | D26: =IF(C26<=0,"n/a",$B$6/C26)
A28: 35,000 SF | B28: Revenue | C28: EBITDA | D28: Payback (yrs)
A29: Downside | B29: ='Returns & Scenarios'!$C$7*$B$19 | C29: =B29-(B29*(Assumptions!$C$52+Assumptions!$C$56+Assumptions!$C$60+Assumptions!$C$61)+B29*'Revenue Build'!$C$35*Assumptions!$C$57+Assumptions!$C$7*(Assumptions!$C$53+Assumptions!$C$54+Assumptions!$C$55)+Capex!$C$7*Assumptions!$C$58+Assumptions!$C$59) | D29: =IF(C29<=0,"n/a",$C$6/C29)
A30: Base | B30: ='Returns & Scenarios'!$C$7*$B$20 | C30: =B30-(B30*(Assumptions!$C$52+Assumptions!$C$56+Assumptions!$C$60+Assumptions!$C$61)+B30*'Revenue Build'!$C$35*Assumptions!$C$57+Assumptions!$C$7*(Assumptions!$C$53+Assumptions!$C$54+Assumptions!$C$55)+Capex!$C$7*Assumptions!$C$58+Assumptions!$C$59) | D30: =IF(C30<=0,"n/a",$C$6/C30)
A31: Upside | B31: ='Returns & Scenarios'!$C$7*$B$21 | C31: =B31-(B31*(Assumptions!$C$52+Assumptions!$C$56+Assumptions!$C$60+Assumptions!$C$61)+B31*'Revenue Build'!$C$35*Assumptions!$C$57+Assumptions!$C$7*(Assumptions!$C$53+Assumptions!$C$54+Assumptions!$C$55)+Capex!$C$7*Assumptions!$C$58+Assumptions!$C$59) | D31: =IF(C31<=0,"n/a",$C$6/C31)
A33: RECONCILIATION AGAINST THE KIX PLAN
B34: KIX plan | C34: This model (35k) | D34: Gap
A35: Stabilised revenue | B35: =Benchmark!$B$23 | C35: =$C$7 | D35: =IF(B35=0,0,C35/B35-1)
A36: Stabilised EBITDA | B36: =Benchmark!$B$24 | C36: =$C$8 | D36: =IF(B36=0,0,C36/B36-1)
A37: EBITDA margin | B37: =Benchmark!$B$24/Benchmark!$B$23 | C37: =$C$9 | D37: =IF(B37=0,0,C37/B37-1)
A38: Buildout / project cost | B38: =Benchmark!$B$25 | C38: =$C$6 | D38: =IF(B38=0,0,C38/B38-1)
A39: Revenue per SF | B39: =Benchmark!$B$26 | C39: ='Revenue Build'!$C$40 | D39: =IF(B39=0,0,C39/B39-1)
A40: Payback (years) | B40: =Benchmark!$B$28 | C40: =$C$12 | D40: =IF(B40=0,0,C40/B40-1)
A42: What has to be true to reach the plan's $5.0M
A43: Raise blended station utilisation well above 20%, or add stations, or push spend per visit materially higher.
A44: Reach roughly 3x the revenue density of the only published ESA entertainment comparable.
A45: Build a real F&B operation — at 15% of revenue, as the benchmark runs, the number is unreachable.
A46: None of these are impossible. All of them are currently assumed rather than evidenced.
...
